Workbook
Name SLA_Target: Assumptions!$C$4
Name Slicer_Area: #N/A
Name Slicer_Carrier_Name: #N/A
Name Slicer_Order_Date__Month: #N/A
Name Slicer_Order_Date__Year: #N/A
Name Slicer_Priority: #N/A
Name Slicer_Region: #N/A
Name Slicer_Timeline: #N/A

Sheet Overview
B2: Supply Chain SLA & Freight Performance Dashboard
B5: Selected Period: Aug 2025 – Jul 2026 | 1,000 Shipments | SLA Target: 90%
B8: =Detail!B3 -> 0.835 | J8: =Detail!B5 -> 165 | O8: =Detail!B6 -> 218688.52 | T8: =Scenario_Analysis!G5 -> 0.926
B11: On-Time Ship Rate | F11: Gap To Target | J11: SLA Breaches | O11: Total Freight Spend | T11: Buffer
B18: 01 PERFORMANCE OVERVIEW
B44: 02 WHERE THE BREACHES CONCENTRATE
B70: 03 DELAY & BUFFER OPTIMIZATION
B96: 04 EXECUTIVE INSIGHTS & MANAGEMENT ACTION
B105: Priority | C105: Area | D105: Finding | E105: Recommended Action | F105: Owner | G105: Timeline
B106: ● High | C106: 🚚 Carrier | D106: RailLink Logistics has the lowest SLA (80.7%) | E106: Put RailLink Logistics on a 90-day improvement plan and shift renewal volume toward Swift Express. | F106: Transport Lead | G106: 0-30 days
B107: ● High | C107: 🏭 Warehouse | D107: Tacoma Coastal Warehouse has the highest breach rate (11.6%) | E107: Run a root cause review: Tacoma → Columbus → Atlanta. | F107: Warehouse Manager | G107: 0-30 days
B108: ● Medium | C108: 🌎 Buffer | D108: Minor delays account for most late shipments | E108: Evaluate +1 buffer day on structurally late lanes. | F108: Network Planning | G108: 30-60 days
B109: ● Medium | C109: 📦 Region | D109: US-Central has the lowest regional SLA (80.8%) | E109: Rebalance US-Central staffing and capacity, and review its warehouse mix. | F109: Regional Manager | G109: 30-60 days
B110: ● Ongoing | C110: 📈 Network | D110: Jul-26 reached 92.3% SLA | E110: Standardize Jul-26 practices; monthly SLA review. | F110: Ops Excellence | G110: Monthly

Sheet Detail
A1: PIVOT 0 - KPI Block | D1: PIVOT 1 - Monthly Trend | I1: PIVOT 2 - Carrier | P1: PIVOT 3 - Warehouse | V1: PIVOT 4 - Region | AB1: PIVOT 5 - Delay Distribution
A3: SLA Compliance Rate | B3: 0.835 | E3: SLA Compliance Rate | F3: Total Shipments | G3: Target | J3: Total Shipments | K3: SLA Breached Shipments | L3: SLA Compliance Rate | M3: Avg Delay When Late | N3: Freight Cost Per Lb | P3: Total Shipments | W3: Total Shipments | X3: Total Freight Cost | Y3: Freight Cost Per Lb | Z3: SLA Compliance Rate | AC3: Total Shipments
A4: SLA Target Gap | B4: -0.065 | D4: 2025 | G4: 0.9 | I4: Apex Freight | J4: 193 | K4: 32 | L4: 0.83419689 | M4: 1.8125 | N4: 0.17283059 | Q4: Minor Delay | R4: On-Time | S4: SLA Breach | T4: Grand Total | V4: US-Central | W4: 177 | X4: 40539.06 | Y4: 0.17039877 | Z4: 0.8079096 | AB4: -1 | AC4: 0.268
A5: SLA Breached Shipments | B5: 165 | D5: Aug | E5: 0.84810127 | F5: 79 | G5: 0.9 | I5: FreightPulse | J5: 210 | K5: 34 | L5: 0.83809524 | M5: 1.5 | N5: 0.16747269 | P5: Atlanta Fulfillment Hub | Q5: 0.090361446 | R5: 0.81325301 | S5: 0.096385542 | T5: 1 | V5: US-East | W5: 171 | X5: 38701.31 | Y5: 0.17182865 | Z5: 0.85964912 | AB5: 0 | AC5: 0.567
A6: Total Freight Cost | B6: 218688.52 | D6: Sep | E6: 0.79569892 | F6: 93 | G6: 0.9 | I6: RailLink Logistics | J6: 192 | K6: 37 | L6: 0.80729167 | M6: 1.7567568 | N6: 0.1655449 | P6: Columbus Regional Depot | Q6: 0.096045198 | R6: 0.8079096 | S6: 0.096045198 | T6: 1 | V6: US-South | W6: 330 | X6: 69709.44 | Y6: 0.17278292 | Z6: 0.82727273 | AB6: 1 | AC6: 0.091
A7: Avg Delay When Late | B7: 1.7454545 | D7: Oct | E7: 0.80263158 | F7: 76 | G7: 0.9 | I7: Swift Express | J7: 198 | K7: 29 | L7: 0.85353535 | M7: 1.9310345 | N7: 0.17869346 | P7: Dallas Consolidation Center | Q7: 0.079268293 | R7: 0.84146341 | S7: 0.079268293 | T7: 1 | V7: US-West | W7: 322 | X7: 69738.71 | Y7: 0.17159905 | Z7: 0.8447205 | AB7: 2 | AC7: 0.041
A8: Modeled Penalty Exposure | B8: 21600 | D8: Nov | E8: 0.76923077 | F8: 65 | G8: 0.9 | I8: Velocity Transport | J8: 207 | K8: 33 | L8: 0.84057971 | M8: 1.7575758 | N8: 0.17517971 | P8: Newark Distribution Center | Q8: 0.064327485 | R8: 0.85964912 | S8: 0.076023392 | T8: 1 | V8: Grand Total | W8: 1000 | X8: 218688.52 | Y8: 0.17179056 | Z8: 0.835 | AB8: 3 | AC8: 0.017
D9: Dec | E9: 0.87837838 | F9: 74 | G9: 0.9 | I9: Grand Total | J9: 1000 | K9: 165 | L9: 0.835 | M9: 1.7454545 | N9: 0.17179056 | P9: Reno Cross-Dock Facility | Q9: 0.060402685 | R9: 0.8590604 | S9: 0.080536913 | T9: 1 | AB9: 4 | AC9: 0.016
D10: 2026 | G10: 0.9 | P10: Tacoma Coastal Warehouse | Q10: 0.052023121 | R10: 0.83236994 | S10: 0.11560694 | T10: 1
D11: Jan | E11: 0.84946237 | F11: 93 | G11: 0.9 | P11: Grand Total | Q11: 0.074 | R11: 0.835 | S11: 0.091 | T11: 1
D12: Feb | E12: 0.81481481 | F12: 81 | G12: 0.9
D13: Mar | E13: 0.81395349 | F13: 86 | G13: 0.9
D14: Apr | E14: 0.79569892 | F14: 93 | G14: 0.9
D15: May | E15: 0.85714286 | F15: 84 | G15: 0.9
D16: Jun | E16: 0.85882353 | F16: 85 | G16: 0.9
D17: Jul | E17: 0.92307692 | F17: 91 | G17: 0.9

Sheet Helper
A1: Helper PIVOT 1
B2: Month | C2: SLA Compliance Rate | D2: Target
B3: 45870 | C3: =GETPIVOTDATA("[Measures].[SLA Compliance Rate]",Detail!$D$3,"[fct_Shipments].[Order_Date (Month)]","[fct_Shipments].[Order_Date (Month)].&[Aug]","[fct_Shipments].[Order_Date (Year)]","[fct_Shipments].[Order_Date (Year)].&[2025]") -> 0.84810127 | D3: 0.9
B4: 45901 | C4: =GETPIVOTDATA("[Measures].[SLA Compliance Rate]",Detail!$D$3,"[fct_Shipments].[Order_Date (Month)]","[fct_Shipments].[Order_Date (Month)].&[Sep]","[fct_Shipments].[Order_Date (Year)]","[fct_Shipments].[Order_Date (Year)].&[2025]") -> 0.79569892 | D4: 0.9
B5: 45931 | C5: =GETPIVOTDATA("[Measures].[SLA Compliance Rate]",Detail!$D$3,"[fct_Shipments].[Order_Date (Month)]","[fct_Shipments].[Order_Date (Month)].&[Oct]","[fct_Shipments].[Order_Date (Year)]","[fct_Shipments].[Order_Date (Year)].&[2025]") -> 0.80263158 | D5: 0.9
B6: 45962 | C6: =GETPIVOTDATA("[Measures].[SLA Compliance Rate]",Detail!$D$3,"[fct_Shipments].[Order_Date (Month)]","[fct_Shipments].[Order_Date (Month)].&[Nov]","[fct_Shipments].[Order_Date (Year)]","[fct_Shipments].[Order_Date (Year)].&[2025]") -> 0.76923077 | D6: 0.9
B7: 45992 | C7: =GETPIVOTDATA("[Measures].[SLA Compliance Rate]",Detail!$D$3,"[fct_Shipments].[Order_Date (Month)]","[fct_Shipments].[Order_Date (Month)].&[Dec]","[fct_Shipments].[Order_Date (Year)]","[fct_Shipments].[Order_Date (Year)].&[2025]") -> 0.87837838 | D7: 0.9
B8: 46023 | C8: =GETPIVOTDATA("[Measures].[SLA Compliance Rate]",Detail!$D$3,"[fct_Shipments].[Order_Date (Month)]","[fct_Shipments].[Order_Date (Month)].&[Jan]","[fct_Shipments].[Order_Date (Year)]","[fct_Shipments].[Order_Date (Year)].&[2026]") -> 0.84946237 | D8: 0.9
B9: 46054 | C9: =GETPIVOTDATA("[Measures].[SLA Compliance Rate]",Detail!$D$2,"[fct_Shipments].[Order_Date (Month)]","[fct_Shipments].[Order_Date (Month)].&[Mar]","[fct_Shipments].[Order_Date (Year)]","[fct_Shipments].[Order_Date (Year)].&[2026]") -> 0.81395349 | D9: 0.9
B10: 46082 | C10: =GETPIVOTDATA("[Measures].[SLA Compliance Rate]",Detail!$D$3,"[fct_Shipments].[Order_Date (Month)]","[fct_Shipments].[Order_Date (Month)].&[Mar]","[fct_Shipments].[Order_Date (Year)]","[fct_Shipments].[Order_Date (Year)].&[2026]") -> 0.81395349 | D10: 0.9
B11: 46113 | C11: =GETPIVOTDATA("[Measures].[SLA Compliance Rate]",Detail!$D$3,"[fct_Shipments].[Order_Date (Month)]","[fct_Shipments].[Order_Date (Month)].&[Apr]","[fct_Shipments].[Order_Date (Year)]","[fct_Shipments].[Order_Date (Year)].&[2026]") -> 0.79569892 | D11: 0.9
B12: 46143 | C12: =GETPIVOTDATA("[Measures].[SLA Compliance Rate]",Detail!$D$3,"[fct_Shipments].[Order_Date (Month)]","[fct_Shipments].[Order_Date (Month)].&[May]","[fct_Shipments].[Order_Date (Year)]","[fct_Shipments].[Order_Date (Year)].&[2026]") -> 0.85714286 | D12: 0.9
B13: 46174 | C13: =GETPIVOTDATA("[Measures].[SLA Compliance Rate]",Detail!$D$3,"[fct_Shipments].[Order_Date (Month)]","[fct_Shipments].[Order_Date (Month)].&[Jun]","[fct_Shipments].[Order_Date (Year)]","[fct_Shipments].[Order_Date (Year)].&[2026]") -> 0.85882353 | D13: 0.9
B14: 46204 | C14: =GETPIVOTDATA("[Measures].[SLA Compliance Rate]",Detail!$D$3,"[fct_Shipments].[Order_Date (Month)]","[fct_Shipments].[Order_Date (Month)].&[Jul]","[fct_Shipments].[Order_Date (Year)]","[fct_Shipments].[Order_Date (Year)].&[2026]") -> 0.92307692 | D14: 0.9
A17: Helper PIVOT 2
B19: Carrier | C19: Total Shipments | D19: SLA Compliance Rate
B20: Swift Express | C20: =GETPIVOTDATA("[Measures].[Total Shipments]",Detail!$I$3,"[dim_Carriers].[Carrier_Name]","[dim_Carriers].[Carrier_Name].&[Swift Express]") -> 198 | D20: =GETPIVOTDATA("[Measures].[SLA Compliance Rate]",Detail!$I$3,"[dim_Carriers].[Carrier_Name]","[dim_Carriers].[Carrier_Name].&[Swift Express]") -> 0.85353535
B21: Velocity Transport | C21: =GETPIVOTDATA("[Measures].[Total Shipments]",Detail!$I$3,"[dim_Carriers].[Carrier_Name]","[dim_Carriers].[Carrier_Name].&[Velocity Transport]") -> 207 | D21: =GETPIVOTDATA("[Measures].[SLA Compliance Rate]",Detail!$I$3,"[dim_Carriers].[Carrier_Name]","[dim_Carriers].[Carrier_Name].&[Velocity Transport]") -> 0.84057971
B22: FreightPulse | C22: =GETPIVOTDATA("[Measures].[Total Shipments]",Detail!$I$3,"[dim_Carriers].[Carrier_Name]","[dim_Carriers].[Carrier_Name].&[FreightPulse]") -> 210 | D22: =GETPIVOTDATA("[Measures].[SLA Compliance Rate]",Detail!$I$3,"[dim_Carriers].[Carrier_Name]","[dim_Carriers].[Carrier_Name].&[FreightPulse]") -> 0.83809524
B23: Apex Freight | C23: =GETPIVOTDATA("[Measures].[Total Shipments]",Detail!$I$3,"[dim_Carriers].[Carrier_Name]","[dim_Carriers].[Carrier_Name].&[Apex Freight]") -> 193 | D23: =GETPIVOTDATA("[Measures].[SLA Compliance Rate]",Detail!$I$3,"[dim_Carriers].[Carrier_Name]","[dim_Carriers].[Carrier_Name].&[Apex Freight]") -> 0.83419689
B24: RailLink Logistics | C24: =GETPIVOTDATA("[Measures].[Total Shipments]",Detail!$I$3,"[dim_Carriers].[Carrier_Name]","[dim_Carriers].[Carrier_Name].&[RailLink Logistics]") -> 192 | D24: =GETPIVOTDATA("[Measures].[SLA Compliance Rate]",Detail!$I$3,"[dim_Carriers].[Carrier_Name]","[dim_Carriers].[Carrier_Name].&[RailLink Logistics]") -> 0.80729167
A34: Key Insights
B35: Average SLA | C35: =AVERAGEIF(Trend[SLA Compliance Rate], ">0",Trend[SLA Compliance Rate]) -> 0.83384604 | D35: Highest Volume | E35: =INDEX(Carrier[Carrier], MATCH(MAX(Carrier[Total Shipments]), Carrier[Total Shipments], 0)) -> FreightPulse
B36: Target Gap | C36: =C35-90% -> -0.066153959
B37: Best Carrier | C37: =INDEX(B20:B24, MATCH(MAX(D20:D24), D20:D24, 0)) -> Swift Express
B38: Lowest Carrier | C38: =INDEX(B20:B24, MATCH(MIN(D20:D24), D20:D24, 0)) -> RailLink Logistics
B39: Trend Insight
B40: ="Average SLA is "&TEXT(C35,"0.0%")& ", "&TEXT(ABS(C36),"0.0%")& " below the 90% target." -> Average SLA is 83.4%, 6.6% below the 90% target. | E40: {=_xlfn.LET( _xlpm.LastMonth,LOOKUP(2,1/(ISNUMBER(C3:C14)),B3:B14), _xlpm.LastSLA,LOOKUP(2,1/(ISNUMBER(C3:C14)),C3:C14), IF( _xlpm.LastSLA>=90%, TEXT(_xlpm.LastMonth,"mmm-yy")&" exceeded the target with "&TEXT(_xlpm.LastSLA,"0.0%"), TEXT(_xlpm.LastMonth,"mmm-yy")&" closed at "&TEXT(_xlpm.LastSLA,"0.0%")&", remaining "&TEXT(90%-_xlpm.LastSLA,"0.0%")&" below target." ))} -> Jul-26 exceeded the target with 92.3%
B41: Best Carrier Insight
B42: ="Best Performer: "&C37& " achieved the highest SLA ("& TEXT(MAX(Carrier[SLA Compliance Rate]),"0.0%")& ")." -> Best Performer: Swift Express achieved the highest SLA (85.4%).
B43: Lowest Carrier Insight
B44: ="Priority Review: "&C38& " recorded the lowest SLA ("& TEXT(MIN(Carrier[SLA Compliance Rate]),"0.0%")& ")." -> Priority Review: RailLink Logistics recorded the lowest SLA (80.7%).
B45: Recommendation
B46: =IF( C35>=90%, "Recommendation: Maintain current operating practices and continue monitoring all carriers to sustain SLA performance above the target.", IF( C35>=85%, "Recommendation: Improve "&C38&" by adopting operational practices demonstrated by "&C37&" to help close the remaining SLA gap.", "Recommendation: Conduct a root-cause analysis for "&C38&", address recurring delays, and implement corrective actions while benchmarking processes used by "&C37&"." )) -> Recommendation: Conduct a root-cause analysis for RailLink Logistics, address recurring delays, and implement corrective actions while benchmarking processes used by Swift Express.
A48: Helper PIVOT 4
B49: Region | C49: SLA Compliance Rate | D49: Total Shipments
B50: US-Central | C50: =GETPIVOTDATA("[Measures].[SLA Compliance Rate]",Detail!$V$3,"[dim_Warehouses].[Region]","[dim_Warehouses].[Region].&[US-Central]") -> 0.8079096 | D50: =GETPIVOTDATA("[Measures].[Total Shipments]",Detail!$V$3,"[dim_Warehouses].[Region]","[dim_Warehouses].[Region].&[US-Central]") -> 177
B51: US-East | C51: =GETPIVOTDATA("[Measures].[SLA Compliance Rate]",Detail!$V$3,"[dim_Warehouses].[Region]","[dim_Warehouses].[Region].&[US-East]") -> 0.85964912 | D51: =GETPIVOTDATA("[Measures].[Total Shipments]",Detail!$V$3,"[dim_Warehouses].[Region]","[dim_Warehouses].[Region].&[US-East]") -> 171
B52: US-South | C52: =GETPIVOTDATA("[Measures].[SLA Compliance Rate]",Detail!$V$3,"[dim_Warehouses].[Region]","[dim_Warehouses].[Region].&[US-South]") -> 0.82727273 | D52: =GETPIVOTDATA("[Measures].[Total Shipments]",Detail!$V$3,"[dim_Warehouses].[Region]","[dim_Warehouses].[Region].&[US-South]") -> 330
B53: US-West | C53: =GETPIVOTDATA("[Measures].[SLA Compliance Rate]",Detail!$V$3,"[dim_Warehouses].[Region]","[dim_Warehouses].[Region].&[US-West]") -> 0.8447205 | D53: =GETPIVOTDATA("[Measures].[Total Shipments]",Detail!$V$3,"[dim_Warehouses].[Region]","[dim_Warehouses].[Region].&[US-West]") -> 322
...

Sheet Scenario_Analysis
B3: Buffer Days Added to Promise Window | C3: 0 | E3: Buffer | F3: Breaches | G3: Compliance | H3: Breach Days | I3: Penalty | J3: Gap
B4: Penalty Rate Per Day | C4: 75 | E4: 0 | F4: =C5 -> 165 | G4: =C6 -> 0.835 | H4: =C7 -> 288 | I4: =C8 -> 21600 | J4: =C9 -> -0.065
B5: Breaches | C5: {=SUMPRODUCT((B12:B17>$C$3)*C12:C17)} -> 165 | E5: 1 | F5: 74 | G5: 0.926 | H5: 123 | I5: 9225 | J5: 0.026 | L5: =(I4-I5)/I4 -> 0.57291667
B6: Compliance Rate | C6: =1 - C5/1000 -> 0.835 | E6: 2 | F6: 33 | G6: 0.967 | H6: 49 | I6: 3675 | J6: 0.067
B7: Breach Days | C7: {=SUMPRODUCT((B12:B17>$C$3)*(B12:B17-$C$3)*C12:C17)} -> 288 | E7: 3 | F7: 16 | G7: 0.984 | H7: 16 | I7: 1200 | J7: 0.084
B8: Penalty Exposure | C8: =C7*C4 -> 21600 | E8: 4 | F8: 0 | G8: 1 | H8: 0 | I8: 0 | J8: 0.1
B9: Gap to Target | C9: =C6 - 0.9 -> -0.065
B11: Delay_Days | C11: Shipments | E11: Key Insight
B12: -1 | C12: 268
B13: 0 | C13: 567
B14: 1 | C14: 91
B15: 2 | C15: 41
B16: 3 | C16: 17
B17: 4 | C17: 16
B18: Static extract from calc_pivots Pivot 5. Refreshed 2026-08-01
B20: Sanity check | C20: =SUM(C12:C17) -> 1000

Sheet Assumptions
B3: Label | C3: Value | D3: Format
B4: SLA Target (On-Time Ship Rate) | C4: 0.9 | D4: Percentage
B5: Penalty per breach-day (USD) | C5: 75 | D5: Currency
B6: Breach Definition | C6: Actual > Promised | D6: Text
B7: Early Shipment Treatment | C7: Count as on-time | D7: Text
B9: Note
B10: The dataset has no penalty field. $75/breach-day is a placeholder; change if you want, but never present it as data.

Sheet raw_Carriers
A1: Carrier_ID | B1: Carrier_Name | C1: SLA_Target_Days | D1: Base_Cost_Per_Shipment
A2: CR-101 | B2: Swift Express | C2: 2 | D2: 21.5
A3: CR-102 | B3: Apex Freight | C3: 3 | D3: 16.75
A4: CR-103 | B4: FreightPulse | C4: 4 | D4: 11.4
A5: CR-104 | B5: RailLink Logistics | C5: 5 | D5: 8.25
A6: CR-105 | B6: Velocity Transport | C6: 3 | D6: 18.9

Sheet raw_Warehouses
A1: Warehouse_ID | B1: Warehouse_Name | C1: Region | D1: Max_Capacity_Units | E1: Handling_Cost_Per_Unit
A2: WH-001 | B2: Newark Distribution Center | C2: US-East | D2: 68500 | E2: 2.15
A3: WH-002 | B3: Atlanta Fulfillment Hub | C3: US-South | D3: 52400 | E3: 1.65
A4: WH-003 | B4: Columbus Regional Depot | C4: US-Central | D4: 45900 | E4: 1.42
A5: WH-004 | B5: Reno Cross-Dock Facility | C5: US-West | D5: 31200 | E5: 2.68
A6: WH-005 | B6: Dallas Consolidation Center | C6: US-South | D6: 74300 | E6: 1.28
A7: WH-006 | B7: Tacoma Coastal Warehouse | C7: US-West | D7: 27800 | E7: 2.44

Sheet raw_Shipments
A1: Shipment_ID | B1: Order_Date | C1: Warehouse_ID | D1: Carrier_ID | E1: Promised_Ship_Date | F1: Actual_Ship_Date | G1: Shipment_Weight_Lbs | H1: Freight_Cost
A2: SHP-10001 | B2: 45870 | C2: WH-006 | D2: CR-105 | E2: 45872 | F2: 45871 | G2: 1491 | H2: 256.89
A3: SHP-10002 | B3: 45870 | C3: WH-005 | D3: CR-103 | E3: 45871 | F3: 45870 | G3: 360 | H3: 78.25
A4: SHP-10003 | B4: 45870 | C4: WH-006 | D4: CR-104 | E4: 45872 | F4: 45874 | G4: 985 | H4: 167.3
A5: SHP-10004 | B5: 45870 | C5: WH-006 | D5: CR-104 | E5: 45872 | F5: 45871 | G5: 2180 | H5: 346.68
A6: SHP-10005 | B6: 45870 | C6: WH-002 | D6: CR-101 | E6: 45872 | F6: 45872 | G6: 1628 | H6: 276.78
A7: SHP-10006 | B7: 45870 | C7: WH-006 | D7: CR-101 | E7: 45872 | F7: 45871 | G7: 143 | H7: 52.4
A8: SHP-10007 | B8: 45871 | C8: WH-004 | D8: CR-103 | E8: 45873 | F8: 45873 | G8: 2286 | H8: 369.23
A9: SHP-10008 | B9: 45871 | C9: WH-004 | D9: CR-104 | E9: 45872 | F9: 45872 | G9: 1480 | H9: 240.25
A10: SHP-10009 | B10: 45871 | C10: WH-002 | D10: CR-103 | E10: 45873 | F10: 45873 | G10: 1945 | H10: 310.01
A11: SHP-10010 | B11: 45872 | C11: WH-001 | D11: CR-101 | E11: 45874 | F11: 45873 | G11: 2171 | H11: 358.5
A12: SHP-10011 | B12: 45873 | C12: WH-005 | D12: CR-103 | E12: 45874 | F12: 45874 | G12: 1626 | H12: 264.05
A13: SHP-10012 | B13: 45873 | C13: WH-001 | D13: CR-103 | E13: 45875 | F13: 45875 | G13: 129 | H13: 48.23
... A1001: SHP-11000 | B1001: 46234 | C1001: WH-005 | D1001: CR-101 | E1001: 46236 | F1001: 46235 | G1001: 547 | H1001: 122.4

Sheet scratch
A1: Total Weight | B1: Freight Cost Per Lb | C1: Avg Order Freight Cost | D1: Modeled Penalty Exposure | E1: Total Freight Cost | F1: Avg Schedule Variance | G1: Avg Delay When Late | H1: Total Breach Days | I1: SLA Target Gap | J1: SLA Compliance Rate | K1: SLA Breached Shipments | L1: On-Time Shipments | M1: Total Shipments
A2: 1272995 | B2: 0.17179056 | C2: 218.68852 | D2: 21600 | E2: 218688.52 | F2: 0.02 | G2: 1.7454545 | H2: 288 | I2: -0.065 | J2: 0.835 | K2: 165 | L2: 835 | M2: 1000
